Workbook

Sheet Cover
B2: Dataset information | F2: Dataset format information
C3: Column name | D3: Dataset entries
A4: 1 | B4: Identification | C4: dataset_id | D4: auto | F4: IEDC data file
A5: 2 | C5: dataset_name | D5: 4_UPI_CIRCOMOD_D4.1
A6: 3 | C6: dataset_version | D6: V1.0 | F6: Format_Version | G6: IEDC_V1
A7: 4 | B7: Grouping | C7: datagroup_id | D7: CIRCOMOD_Task4.2_Process_Descriptions | F7: Dataset_Unit | G7: LIST
A8: 5 | C8: data_category | D8: 4 | F8: Dataset_Uncertainty | G8: LIST
A9: 6 | C9: data_type | D9: Unit process inventory | F9: Dataset_Comment | G9: LIST
A10: 7 | C10: data_layer | D10: Misc. physical units | F10: Dataset_RecordType | G10: LIST | H10: No_Rows | I10: 4386
A11: 8 | B11: System location: What elements and objects in the system are described? | C11: process_scope | D11: Material production processes | F11: Aspects_classifications | G11: Aspects_Attribute_No | H11: DATA | I11: DATA_Info
A12: 9 | C12: process_resolution | D12: project-wide material and waste production/treatment processes | F12: process | G12: 1 | H12: value
A13: 10 | C13: product_scope | D13: none | F13: material | G13: 1 | H13: unit nominator
A14: 11 | C14: product_resolution | D14: none | F14: material_category | G14: 1 | H14: unit denominator
A15: 12 | C15: material_scope | D15: Materials and waste | F15: layer | G15: 1 | H15: stats_array_string
A16: 13 | C16: material_resolution | D16: project-wide material and waste groups | H16: comment
A17: 14 | C17: regional_scope | D17: Global
A18: 15 | C18: regional_resolution | D18: process specific
A19: 16 | C19: temporal_scope | D19: 1970-2100
A20: 17 | C20: temporal_resolution | D20: process specific
A21: 18 | B21: Description | C21: description | D21: Unit process inventory for various material production and waste treatment processes studied by the CIRCOMOD models
A22: 19 | C22: keywords | D22: material production; recycling; unit process;
A23: 20 | C23: data_provenance | D23: Result of academic MFA work
A24: 21 | C24: dataset_size | D24: 4386
A25: 22 | C25: comment
A26: 23 | B26: System location: Dataset aspects and semantics. For aspects: [Aspect;symbol;classification]. Mandatory aspects in gray shading. | C26: aspect_1 | D26: process
A27: 24 | C27: aspect_1_classification | D27: 82
A28: 25 | C28: aspect_2 | D28: material
A29: 26 | C29: aspect_2_classification | D29: 83
A30: 27 | C30: aspect_3 | D30: material_category
A31: 28 | C31: aspect_3_classification | D31: 84
A32: 29 | C32: aspect_4 | D32: layer
A33: 30 | C33: aspect_4_classification | D33: 20
A34: 31 | C34: aspect_5 | D34: none
A35: 32 | C35: aspect_5_classification | D35: none
A36: 33 | C36: aspect_6 | D36: none
A37: 34 | C37: aspect_6_classification | D37: none
A38: 35 | C38: aspect_7 | D38: none
A39: 36 | C39: aspect_7_classification | D39: none
A40: 37 | C40: aspect_8 | D40: none
A41: 38 | C41: aspect_8_classification | D41: none
...

Sheet Data
A1: process | B1: material | C1: material_category | D1: layer | E1: value | F1: unit nominator | G1: unit denominator | H1: stats_array string | I1: comment | J1: link to log entry | K1: Data source | L1: material_group
A2: [a] Beneficiation, sulfide ore (Crushing, grinding, flotation) | B2: copper concentrate, sulfide ore | C2: reference_product | D2: mass | E2: 1 | F2: t | G2: 1 | H2: none | J2: [PU] Sulf_Ore_Conc | K2: See log sheet | L2: 2603
A3: [a] Beneficiation, sulfide ore (Crushing, grinding, flotation) | B3: sulphide ore | C3: from environment (natural resource) | D3: mass | E3: 4 | F3: t | G3: t | H3: none | J3: [PU] Sulf_Ore_Conc | K3: See log sheet
A4: [a] Beneficiation, sulfide ore (Crushing, grinding, flotation) | B4: electricity | C4: from technosphere (energy_carrier) | D4: energy | E4: 16.4 | F4: kWh | G4: t | H4: none | J4: [PU] Sulf_Ore_Conc | K4: See log sheet
A5: [a] Beneficiation, sulfide ore (Crushing, grinding, flotation) | B5: water | C5: from environment (natural resource) | D5: volume | E5: 0.6 | F5: m3 | G5: t | H5: none | J5: [PU] Sulf_Ore_Conc | K5: See log sheet
A6: [a] Beneficiation, sulfide ore (Crushing, grinding, flotation) | B6: steel | C6: from technosphere (material) | D6: mass | E6: 0.7 | F6: t | G6: t | H6: none | J6: [PU] Sulf_Ore_Conc | K6: See log sheet
A7: [a] Beneficiation, sulfide ore (Crushing, grinding, flotation) | B7: quicklime | C7: from technosphere (material) | D7: mass | E7: 1 | F7: t | G7: t | H7: none | J7: [PU] Sulf_Ore_Conc | K7: See log sheet
A8: [a] Beneficiation, sulfide ore (Crushing, grinding, flotation) | B8: other chemicals | C8: from technosphere (material) | D8: mass | E8: 0.13 | F8: t | G8: t | H8: none | J8: [PU] Sulf_Ore_Conc | K8: See log sheet
A9: [a] Beneficiation, sulfide ore (Crushing, grinding, flotation) | B9: water | C9: to environment (emission) | D9: volume | E9: 0.6 | F9: m3 | G9: t | H9: none | J9: [PU] Sulf_Ore_Conc | K9: See log sheet
A10: [a] Beneficiation, sulfide ore (Crushing, grinding, flotation) | B10: tailings | C10: to technosphere (waste) | D10: mass | E10: 5.83 | F10: t | G10: t | H10: none | J10: [PU] Sulf_Ore_Conc | K10: See log sheet
A11: [a] Calcined clay, flash calciner | B11: metakaolin | C11: reference_product | D11: mass | E11: 1 | F11: t | G11: 1 | H11: none | J11: [a] Calcined clay, flash calciner | K11: Martinez et al. 2023 [117] | L11: 2507
A12: [a] Calcined clay, flash calciner | B12: kaolinite, dry | C12: from environment (natural resource) | D12: mass | E12: 1.16 | F12: t | G12: 1 | H12: none | J12: [a] Calcined clay, flash calciner | K12: Martinez et al. 2023 [117]
A13: [a] Calcined clay, flash calciner | B13: industrial heat, high-temperature | C13: from technosphere (energy_carrier) | D13: energy | E13: 2.7 | F13: GJ | G13: 1 | H13: values found in literature (usually no information given about water content of clay): 2.7 GJ/tonne (Cancio Díaz et al. 2017); 2.8 GJ/tonne (Sánchez Berriel et al. 2016); 3.7 GJ/tonne (Martinez et al. 2023); (not specifying the calcination technology, based on theoretical calculations, but including estimated efficiency loss, Gettu et al. (2018) and Hanein et al. (2021) report values of 2.6 GJ/tonne and 2.2-3 GJ/tonne (for 0 w% water content of clay and assumed thermal process efficiency of 50-70%), respectively) | J13: [a] Calcined clay, flash calciner | K13: Martinez et al. 2023 [117]
A14: [a] Calcined clay, flash calciner | B14: electricity | C14: from technosphere (energy_carrier) | D14: energy | E14: 0.051 | F14: GJ | G14: 1 | H14: none | J14: [a] Calcined clay, flash calciner | K14: Martinez et al. 2023 [117]
A15: [a] Calcined clay, flash calciner | B15: carbon dioxide | C15: to environment (emission, process) | D15: mass | E15: 0.03 | F15: t | G15: 1 | H15: none | I15: Value for electricity demand for "grinding + packing + other" for rotary kiln based industrial scale Metakoalin-Limestone Cement production (Best available technology, flash calciner based production, | J15: [a] Calcined clay, flash calciner | K15: Sánchez Berriel et al. 2016 [116]
A16: [a] Calcined clay, rotary kiln | B16: metakaolin | C16: reference_product | D16: mass | E16: 1 | F16: t | G16: 1 | H16: none | I16: A key determinant of the energy requirements of calcined clay is the moisture content of the used clay. This can highly vary, not only due to the composition of the clay, but also depending on the climatic and weather conditions at the mining site. The moisture content can be as low as a few percent, but can also reach more than 40 wt%. Reducing the free water content/moisture of the clay requires about 600 kJ/kg at 20 wt% of the clay and 1500 kJ/kg at 40 wt%, not considering thermal process efficiency, which varies between 50 and 70 % (Hanein et al. 2021, 20) | J16: [a] Calcined clay, rotary kiln | K16: Hanein et al. 2021 [114] | L16: 2507
A17: [a] Calcined clay, rotary kiln | B17: kaolinite, dry | C17: from environment (natural resource) | D17: mass | E17: 1.16 | F17: t | G17: 1 | H17: none | I17: energy demand (high temperature heat) for dry (0 w% water content) kaolinite input - value taken from Cancio Díaz et al. 2017, which report the lowest value among the studies specifying the calcination technology used; ~900°C used for industrial scale clay calcination in kiln calcination | J17: [a] Calcined clay, rotary kiln | K17: Cancio Díaz et al. 2017 [115]
A18: [a] Calcined clay, rotary kiln | B18: industrial heat, high-temperature | C18: from technosphere (energy_carrier) | D18: energy | E18: 3.1 | F18: GJ | G18: 1 | H18: values found in literature (usually no information given about water content of clay): 3.1 GJ/tonne (Cancio Díaz et al. 2017); 3.2 GJ/tonne (Sánchez Berriel et al. 2016); 4.4 GJ/tonne (Martinez et al. 2023); (not specifying the calcination technology, based on theoretical calculations, but including estimated efficiency loss, Gettu et al. (2018) and Hanein et al. (2021) report values of 2.6 GJ/tonne and 2.2-3 GJ/tonne (for 0 w% water content of clay and assumed thermal process efficiency of 50-70%), respectively) | J18: [a] Calcined clay, rotary kiln | K18: Sánchez Berriel et al. 2016 [116]
A19: [a] Calcined clay, rotary kiln | B19: electricity | C19: from technosphere (energy_carrier) | D19: energy | E19: 0.165 | F19: GJ | G19: 1 | H19: none | I19: “The values of less than 30 g CO2 for clays are based on the assumption that the clay will contain\3 wt% CO2” (Hanein et al. 2021, 21) | J19: [a] Calcined clay, rotary kiln | K19: Hanein et al. 2021 [114]
A20: [a] Calcined clay, rotary kiln | B20: carbon dioxide | C20: to environment (emission, process) | D20: mass | E20: 0.03 | F20: t | G20: 1 | H20: none | J20: [a] Calcined clay, rotary kiln
A21: [a] Copper anode production (Bath smelting and converting) | B21: copper, anode | C21: reference_product | D21: mass | E21: 1 | F21: kg | G21: 1 | H21: none | J21: [PU] Pyro_Bath_Copper | K21: See log sheet | L21: 7402
A22: [a] Copper anode production (Bath smelting and converting) | B22: copper concentrate, sulfide ore | C22: from technosphere (material) | D22: mass | E22: 3.57 | F22: kg | G22: kg | H22: none | J22: [PU] Pyro_Bath_Copper | K22: See log sheet
A23: [a] Copper anode production (Bath smelting and converting) | B23: sulfuric acid | C23: to technosphere (by-product) | D23: mass | E23: 1.52 | F23: kg | G23: kg | H23: none | J23: [PU] Pyro_Bath_Copper | K23: See log sheet | L23: 2807
A24: [a] Copper anode production (Bath smelting and converting) | B24: fuel oil | C24: from technosphere (energy_carrier) | D24: energy | E24: 4.18 | F24: MJ | G24: kg | H24: none | J24: [PU] Pyro_Bath_Copper | K24: See log sheet
A25: [a] Copper anode production (Bath smelting and converting) | B25: electricity | C25: from technosphere (energy_carrier) | D25: energy | E25: 6.9 | F25: MJ | G25: kg | H25: none | J25: [PU] Pyro_Bath_Copper | K25: See log sheet
A26: [a] Copper anode production (Bath smelting and converting) | B26: oxygen | C26: from environment (natural resource) | D26: mass | E26: 2.79 | F26: kg | G26: kg | H26: none | J26: [PU] Pyro_Bath_Copper | K26: See log sheet
A27: [a] Copper anode production (Bath smelting and converting) | B27: industrial oxygen | C27: from technosphere (material) | D27: mass | E27: 1.27 | F27: kg | G27: kg | H27: none | J27: [PU] Pyro_Bath_Copper | K27: See log sheet
A28: [a] Copper anode production (Bath smelting and converting) | B28: silca flux | C28: from technosphere (material) | D28: mass | E28: 0.355 | F28: kg | G28: kg | H28: none | J28: [PU] Pyro_Bath_Copper | K28: See log sheet
A29: [a] Copper anode production (Bath smelting and converting) | B29: limestone | C29: from environment (natural resource) | D29: mass | E29: 0.127 | F29: kg | G29: kg | H29: none | J29: [PU] Pyro_Bath_Copper | K29: See log sheet
A30: [a] Copper anode production (Bath smelting and converting) | B30: scrap | C30: from technosphere (other) | D30: mass | E30: 0.0423 | F30: kg | G30: kg | H30: none | J30: [PU] Pyro_Bath_Copper | K30: See log sheet
A31: [a] Copper anode production (Bath smelting and converting) | B31: water | C31: from environment (natural resource) | D31: mass | E31: 0.355 | F31: kg | G31: kg | H31: none | J31: [PU] Pyro_Bath_Copper | K31: See log sheet
A32: [a] Copper anode production (Bath smelting and converting) | B32: sulfur dioxide | C32: to environment (emission) | D32: mass | E32: 0.45 | F32: kg | G32: kg | H32: none | J32: [PU] Pyro_Bath_Copper | K32: See log sheet | L32: 2807
A33: [a] Copper anode production (Bath smelting and converting) | B33: carbon dioxide | C33: to environment (emission) | D33: mass | E33: 0.39 | F33: kg | G33: kg | H33: none | J33: [PU] Pyro_Bath_Copper | K33: See log sheet | L33: 2520
A34: [a] Copper anode production (Bath smelting and converting) | B34: slag | C34: to technosphere (waste) | D34: mass | E34: 1.91 | F34: kg | G34: kg | H34: none | J34: [PU] Pyro_Bath_Copper | K34: See log sheet
A35: [a] Copper anode production (Continuous smelting and converting) | B35: copper, anode | C35: reference_product | D35: mass | E35: 1 | F35: kg | G35: 1 | H35: none | J35: [PU] Pyro_Cont_Copper | K35: See log sheet | L35: 7402
A36: [a] Copper anode production (Continuous smelting and converting) | B36: copper concentrate, sulfide ore | C36: from technosphere (material) | D36: mass | E36: 3.57 | F36: kg | G36: kg | H36: none | J36: [PU] Pyro_Cont_Copper | K36: See log sheet
A37: [a] Copper anode production (Continuous smelting and converting) | B37: sulfuric acid | C37: to technosphere (by-product) | D37: mass | E37: 2.48 | F37: kg | G37: kg | H37: none | J37: [PU] Pyro_Cont_Copper | K37: See log sheet | L37: 2807
A38: [a] Copper anode production (Continuous smelting and converting) | B38: fuel oil | C38: from technosphere (energy_carrier) | D38: energy | E38: 2.5 | F38: MJ | G38: kg | H38: none | J38: [PU] Pyro_Cont_Copper | K38: See log sheet
A39: [a] Copper anode production (Continuous smelting and converting) | B39: electricity | C39: from technosphere (energy_carrier) | D39: energy | E39: 8.51 | F39: MJ | G39: kg | H39: none | J39: [PU] Pyro_Cont_Copper | K39: See log sheet
A40: [a] Copper anode production (Continuous smelting and converting) | B40: oxygen | C40: from environment (natural resource) | D40: mass | E40: 2.71 | F40: kg | G40: kg | H40: none | J40: [PU] Pyro_Cont_Copper | K40: See log sheet
...

Sheet Data_old
A1: process | B1: material | C1: material_category | D1: layer | E1: value | F1: unit nominator | G1: unit denominator | H1: stats_array string | I1: comment | J1: link to log entry | K1: Data source | L1: material_group
A2: [a] Beneficiation, sulfide ore (Crushing, grinding, flotation) | B2: copper concentrate, sulfide ore | C2: reference_product | D2: mass | E2: 1 | F2: t | G2: 1 | H2: none | J2: [PU] Sulf_Ore_Conc | K2: See log sheet | L2: 2603
A3: [a] Beneficiation, sulfide ore (Crushing, grinding, flotation) | B3: sulphide ore | C3: from environment (natural resource) | D3: mass | E3: 4 | F3: t | G3: t | H3: none | J3: [PU] Sulf_Ore_Conc | K3: See log sheet
A4: [a] Beneficiation, sulfide ore (Crushing, grinding, flotation) | B4: electricity | C4: from technosphere (energy_carrier) | D4: energy | E4: 16.4 | F4: kWh | G4: t | H4: none | J4: [PU] Sulf_Ore_Conc | K4: See log sheet
A5: [a] Beneficiation, sulfide ore (Crushing, grinding, flotation) | B5: water | C5: from environment (natural resource) | D5: volume | E5: 0.6 | F5: m3 | G5: t | H5: none | J5: [PU] Sulf_Ore_Conc | K5: See log sheet
A6: [a] Beneficiation, sulfide ore (Crushing, grinding, flotation) | B6: steel | C6: from technosphere (material) | D6: mass | E6: 0.7 | F6: t | G6: t | H6: none | J6: [PU] Sulf_Ore_Conc | K6: See log sheet
A7: [a] Beneficiation, sulfide ore (Crushing, grinding, flotation) | B7: quicklime | C7: from technosphere (material) | D7: mass | E7: 1 | F7: t | G7: t | H7: none | J7: [PU] Sulf_Ore_Conc | K7: See log sheet
A8: [a] Beneficiation, sulfide ore (Crushing, grinding, flotation) | B8: other chemicals | C8: from technosphere (material) | D8: mass | E8: 0.13 | F8: t | G8: t | H8: none | J8: [PU] Sulf_Ore_Conc | K8: See log sheet
A9: [a] Beneficiation, sulfide ore (Crushing, grinding, flotation) | B9: water | C9: to environment (emission) | D9: volume | E9: 0.6 | F9: m3 | G9: t | H9: none | J9: [PU] Sulf_Ore_Conc | K9: See log sheet
A10: [a] Beneficiation, sulfide ore (Crushing, grinding, flotation) | B10: tailings | C10: to technosphere (waste) | D10: mass | E10: 5.83 | F10: t | G10: t | H10: none | J10: [PU] Sulf_Ore_Conc | K10: See log sheet
A11: [a] Calcined clay, flash calciner | B11: metakaolin | C11: reference_product | D11: mass | E11: 1 | F11: t | G11: 1 | H11: none | J11: [a] Calcined clay, flash calciner | K11: Martinez et al. 2023 [117] | L11: 2507
A12: [a] Calcined clay, flash calciner | B12: kaolinite, dry | C12: from environment (natural resource) | D12: mass | E12: 1.16 | F12: t | G12: 1 | H12: none | J12: [a] Calcined clay, flash calciner | K12: Martinez et al. 2023 [117]
A13: [a] Calcined clay, flash calciner | B13: industrial heat, high-temperature | C13: from technosphere (energy_carrier) | D13: energy | E13: 2.7 | F13: GJ | G13: 1 | H13: values found in literature (usually no information given about water content of clay): 2.7 GJ/tonne (Cancio Díaz et al. 2017); 2.8 GJ/tonne (Sánchez Berriel et al. 2016); 3.7 GJ/tonne (Martinez et al. 2023); (not specifying the calcination technology, based on theoretical calculations, but including estimated efficiency loss, Gettu et al. (2018) and Hanein et al. (2021) report values of 2.6 GJ/tonne and 2.2-3 GJ/tonne (for 0 w% water content of clay and assumed thermal process efficiency of 50-70%), respectively) | J13: [a] Calcined clay, flash calciner | K13: Martinez et al. 2023 [117]
A14: [a] Calcined clay, flash calciner | B14: electricity | C14: from technosphere (energy_carrier) | D14: energy | E14: 0.051 | F14: GJ | G14: 1 | H14: none | J14: [a] Calcined clay, flash calciner | K14: Martinez et al. 2023 [117]
A15: [a] Calcined clay, flash calciner | B15: carbon dioxide | C15: to environment (emission, process) | D15: mass | E15: 0.03 | F15: t | G15: 1 | H15: none | I15: Value for electricity demand for "grinding + packing + other" for rotary kiln based industrial scale Metakoalin-Limestone Cement production (Best available technology, flash calciner based production, | J15: [a] Calcined clay, flash calciner | K15: Sánchez Berriel et al. 2016 [116]
A16: [a] Calcined clay, rotary kiln | B16: metakaolin | C16: reference_product | D16: mass | E16: 1 | F16: t | G16: 1 | H16: none | I16: A key determinant of the energy requirements of calcined clay is the moisture content of the used clay. This can highly vary, not only due to the composition of the clay, but also depending on the climatic and weather conditions at the mining site. The moisture content can be as low as a few percent, but can also reach more than 40 wt%. Reducing the free water content/moisture of the clay requires about 600 kJ/kg at 20 wt% of the clay and 1500 kJ/kg at 40 wt%, not considering thermal process efficiency, which varies between 50 and 70 % (Hanein et al. 2021, 20) | J16: [a] Calcined clay, rotary kiln | K16: Hanein et al. 2021 [114] | L16: 2507
A17: [a] Calcined clay, rotary kiln | B17: kaolinite, dry | C17: from environment (natural resource) | D17: mass | E17: 1.16 | F17: t | G17: 1 | H17: none | I17: energy demand (high temperature heat) for dry (0 w% water content) kaolinite input - value taken from Cancio Díaz et al. 2017, which report the lowest value among the studies specifying the calcination technology used; ~900°C used for industrial scale clay calcination in kiln calcination | J17: [a] Calcined clay, rotary kiln | K17: Cancio Díaz et al. 2017 [115]
A18: [a] Calcined clay, rotary kiln | B18: industrial heat, high-temperature | C18: from technosphere (energy_carrier) | D18: energy | E18: 3.1 | F18: GJ | G18: 1 | H18: values found in literature (usually no information given about water content of clay): 3.1 GJ/tonne (Cancio Díaz et al. 2017); 3.2 GJ/tonne (Sánchez Berriel et al. 2016); 4.4 GJ/tonne (Martinez et al. 2023); (not specifying the calcination technology, based on theoretical calculations, but including estimated efficiency loss, Gettu et al. (2018) and Hanein et al. (2021) report values of 2.6 GJ/tonne and 2.2-3 GJ/tonne (for 0 w% water content of clay and assumed thermal process efficiency of 50-70%), respectively) | J18: [a] Calcined clay, rotary kiln | K18: Sánchez Berriel et al. 2016 [116]
A19: [a] Calcined clay, rotary kiln | B19: electricity | C19: from technosphere (energy_carrier) | D19: energy | E19: 0.165 | F19: GJ | G19: 1 | H19: none | I19: “The values of less than 30 g CO2 for clays are based on the assumption that the clay will contain\3 wt% CO2” (Hanein et al. 2021, 21) | J19: [a] Calcined clay, rotary kiln | K19: Hanein et al. 2021 [114]
A20: [a] Calcined clay, rotary kiln | B20: carbon dioxide | C20: to environment (emission, process) | D20: mass | E20: 0.03 | F20: t | G20: 1 | H20: none | J20: [a] Calcined clay, rotary kiln
A21: [a] Copper anode production (Bath smelting and converting) | B21: copper, anode | C21: reference_product | D21: mass | E21: 1 | F21: kg | G21: 1 | H21: none | J21: [PU] Pyro_Bath_Copper | K21: See log sheet | L21: 7402
A22: [a] Copper anode production (Bath smelting and converting) | B22: copper concentrate, sulfide ore | C22: from technosphere (material) | D22: mass | E22: 3.57 | F22: kg | G22: kg | H22: none | J22: [PU] Pyro_Bath_Copper | K22: See log sheet
A23: [a] Copper anode production (Bath smelting and converting) | B23: sulfuric acid | C23: to technosphere (by-product) | D23: mass | E23: 1.52 | F23: kg | G23: kg | H23: none | J23: [PU] Pyro_Bath_Copper | K23: See log sheet | L23: 2807
A24: [a] Copper anode production (Bath smelting and converting) | B24: fuel oil | C24: from technosphere (energy_carrier) | D24: energy | E24: 4.18 | F24: MJ | G24: kg | H24: none | J24: [PU] Pyro_Bath_Copper | K24: See log sheet
A25: [a] Copper anode production (Bath smelting and converting) | B25: electricity | C25: from technosphere (energy_carrier) | D25: energy | E25: 6.9 | F25: MJ | G25: kg | H25: none | J25: [PU] Pyro_Bath_Copper | K25: See log sheet
A26: [a] Copper anode production (Bath smelting and converting) | B26: oxygen | C26: from environment (natural resource) | D26: mass | E26: 2.79 | F26: kg | G26: kg | H26: none | J26: [PU] Pyro_Bath_Copper | K26: See log sheet
A27: [a] Copper anode production (Bath smelting and converting) | B27: industrial oxygen | C27: from technosphere (material) | D27: mass | E27: 1.27 | F27: kg | G27: kg | H27: none | J27: [PU] Pyro_Bath_Copper | K27: See log sheet
A28: [a] Copper anode production (Bath smelting and converting) | B28: silca flux | C28: from technosphere (material) | D28: mass | E28: 0.355 | F28: kg | G28: kg | H28: none | J28: [PU] Pyro_Bath_Copper | K28: See log sheet
A29: [a] Copper anode production (Bath smelting and converting) | B29: limestone | C29: from environment (natural resource) | D29: mass | E29: 0.127 | F29: kg | G29: kg | H29: none | J29: [PU] Pyro_Bath_Copper | K29: See log sheet
A30: [a] Copper anode production (Bath smelting and converting) | B30: scrap | C30: from technosphere (other) | D30: mass | E30: 0.0423 | F30: kg | G30: kg | H30: none | J30: [PU] Pyro_Bath_Copper | K30: See log sheet
A31: [a] Copper anode production (Bath smelting and converting) | B31: water | C31: from environment (natural resource) | D31: mass | E31: 0.355 | F31: kg | G31: kg | H31: none | J31: [PU] Pyro_Bath_Copper | K31: See log sheet
A32: [a] Copper anode production (Bath smelting and converting) | B32: sulfur dioxide | C32: to environment (emission) | D32: mass | E32: 0.45 | F32: kg | G32: kg | H32: none | J32: [PU] Pyro_Bath_Copper | K32: See log sheet | L32: 2807
A33: [a] Copper anode production (Bath smelting and converting) | B33: carbon dioxide | C33: to environment (emission) | D33: mass | E33: 0.39 | F33: kg | G33: kg | H33: none | J33: [PU] Pyro_Bath_Copper | K33: See log sheet | L33: 2520
A34: [a] Copper anode production (Bath smelting and converting) | B34: slag | C34: to technosphere (waste) | D34: mass | E34: 1.91 | F34: kg | G34: kg | H34: none | J34: [PU] Pyro_Bath_Copper | K34: See log sheet
A35: [a] Copper anode production (Continuous smelting and converting) | B35: copper, anode | C35: reference_product | D35: mass | E35: 1 | F35: kg | G35: 1 | H35: none | J35: [PU] Pyro_Cont_Copper | K35: See log sheet | L35: 7402
A36: [a] Copper anode production (Continuous smelting and converting) | B36: copper concentrate, sulfide ore | C36: from technosphere (material) | D36: mass | E36: 3.57 | F36: kg | G36: kg | H36: none | J36: [PU] Pyro_Cont_Copper | K36: See log sheet
A37: [a] Copper anode production (Continuous smelting and converting) | B37: sulfuric acid | C37: to technosphere (by-product) | D37: mass | E37: 2.48 | F37: kg | G37: kg | H37: none | J37: [PU] Pyro_Cont_Copper | K37: See log sheet | L37: 2807
A38: [a] Copper anode production (Continuous smelting and converting) | B38: fuel oil | C38: from technosphere (energy_carrier) | D38: energy | E38: 2.5 | F38: MJ | G38: kg | H38: none | J38: [PU] Pyro_Cont_Copper | K38: See log sheet
A39: [a] Copper anode production (Continuous smelting and converting) | B39: electricity | C39: from technosphere (energy_carrier) | D39: energy | E39: 8.51 | F39: MJ | G39: kg | H39: none | J39: [PU] Pyro_Cont_Copper | K39: See log sheet
A40: [a] Copper anode production (Continuous smelting and converting) | B40: oxygen | C40: from environment (natural resource) | D40: mass | E40: 2.71 | F40: kg | G40: kg | H40: none | J40: [PU] Pyro_Cont_Copper | K40: See log sheet
...

Sheet log
A2: Log entry name (link to column I on Data sheet) | B2: Which process? (check CM_1: material_processing_technologies for existing labels) | C2: Which NACE_rev2 code? Does the process cover the entire NACE (revision 2) code category or only part of it? See iedc classification 57 or https://github.com/IndEcol/SEM_classifications/blob/master/processes/IEDC_57_NACE_REV2.xlsx for a complete list) | D2: Date | E2: Who | F2: What - detailed description | G2: List items of ref sheet used
A3: [IMAGE] DRY | B3: Standard dry feed rotary kiln | C3: Part of 23.51 (Manufacture of cement) | D3: 45092 | E3: zotin | F3: Input data used in the IMAGE model, see also van Ruijven et al. (2016) and van Sluisveld et al. (2021). | G3: 2,3,4,5
F4: Additional comments, assumptions, and proxy choices made: | L4: {=IFERROR(VLOOKUP(A10,Data_old!$A:$J,Data_old!$A:$A,FALSE),"")}
F5: Tbd. | L5: {=IFERROR(VLOOKUP(A11,Data_old!$A:$J,Data_old!$A:$A,FALSE),"")}
F6: Qualitative evaluation of the data | L6: {=IFERROR(VLOOKUP(A12,Data_old!$A:$J,Data_old!$A:$A,FALSE),"")}
F7: Tbd. | L7: {=IFERROR(VLOOKUP(A13,Data_old!$A:$J,Data_old!$A:$A,FALSE),"")}
L8: {=IFERROR(VLOOKUP(A14,Data_old!$A:$J,Data_old!$A:$A,FALSE),"")}
A9: [IMAGE] EFD | B9: Efficient dry feed rotary kiln | C9: Part of 23.51 (Manufacture of cement) | D9: 45092 | E9: zotin | F9: Input data used in the IMAGE model, see also van Ruijven et al. (2016) and van Sluisveld et al. (2021). | G9: 2,3,4,5 | L9: {=IFERROR(VLOOKUP(A15,Data_old!$A:$J,Data_old!$A:$A,FALSE),"")}
F10: Additional comments, assumptions, and proxy choices made: | L10: {=IFERROR(VLOOKUP(A16,Data_old!$A:$J,Data_old!$A:$A,FALSE),"")}
F11: Tbd. | L11: {=IFERROR(VLOOKUP(A17,Data_old!$A:$J,Data_old!$A:$A,FALSE),"")}
F12: Qualitative evaluation of the data | L12: {=IFERROR(VLOOKUP(A18,Data_old!$A:$J,Data_old!$A:$A,FALSE),"")}
F13: Tbd. | L13: {=IFERROR(VLOOKUP(A19,Data_old!$A:$J,Data_old!$A:$A,FALSE),"")}
L14: {=IFERROR(VLOOKUP(A20,Data_old!$A:$J,Data_old!$A:$A,FALSE),"")}
A15: [IMAGE] EFD+CCS1 | B15: Efficient dry feed rotary kiln + on-site CCS | C15: Part of 23.51 (Manufacture of cement) | D15: 45092 | E15: zotin | F15: Input data used in the IMAGE model, see also van Ruijven et al. (2016) and van Sluisveld et al. (2021). | G15: 2,3,4,5 | L15: {=IFERROR(VLOOKUP(A21,Data_old!$A:$J,Data_old!$A:$A,FALSE),"")}
F16: Additional comments, assumptions, and proxy choices made: | L16: {=IFERROR(VLOOKUP(A22,Data_old!$A:$J,Data_old!$A:$A,FALSE),"")}
F17: Tbd. | L17: {=IFERROR(VLOOKUP(A23,Data_old!$A:$J,Data_old!$A:$A,FALSE),"")}
F18: Qualitative evaluation of the data | L18: {=IFERROR(VLOOKUP(A24,Data_old!$A:$J,Data_old!$A:$A,FALSE),"")}
F19: Tbd. | L19: {=IFERROR(VLOOKUP(A25,Data_old!$A:$J,Data_old!$A:$A,FALSE),"")}
L20: {=IFERROR(VLOOKUP(A26,Data_old!$A:$J,Data_old!$A:$A,FALSE),"")}
A21: [IMAGE] EFD+CCS2 | B21: Efficient dry feed rotary kiln + oxy-combustion CCS | C21: Part of 23.51 (Manufacture of cement) | D21: 45092 | E21: zotin | F21: Input data used in the IMAGE model, see also van Ruijven et al. (2016) and van Sluisveld et al. (2021). | G21: 2,3,4,5
F22: Additional comments, assumptions, and proxy choices made:
F23: Tbd.
F24: Qualitative evaluation of the data
F25: Tbd.
A27: [IMAGE] BF/BOF | B27: Blast Furnace + Basic Oxygen Furnace | C27: Part of 24.1 (Manufacture of basic iron and steel and of ferro-alloys) | D27: 45092 | E27: zotin | F27: Input data used in the IMAGE model, see also van Ruijven et al. (2016) and van Sluisveld et al. (2021). | G27: 2,3,4,5
F28: Additional comments, assumptions, and proxy choices made:
F29: Tbd.
F30: Qualitative evaluation of the data
F31: Tbd.
A33: [IMAGE] DRI/EAF | B33: Direct Reduced Iron + Electric Arc Furnace | C33: Part of 24.1 (Manufacture of basic iron and steel and of ferro-alloys) | D33: 45092 | E33: zotin | F33: Input data used in the IMAGE model, see also van Ruijven et al. (2016) and van Sluisveld et al. (2021). | G33: 2,3,4,5
F34: Additional comments, assumptions, and proxy choices made:
F35: Tbd.
F36: Qualitative evaluation of the data
F37: Tbd.
A39: [IMAGE] EAF-scrap | B39: Standard Electric Arc Furnace - Scrap | C39: Part of 24.1 (Manufacture of basic iron and steel and of ferro-alloys) | D39: 45092 | E39: zotin | F39: Input data used in the IMAGE model, see also van Ruijven et al. (2016) and van Sluisveld et al. (2021). | G39: 2,3,4,5
F40: Additional comments, assumptions, and proxy choices made:
F41: Tbd.
F42: Qualitative evaluation of the data
F43: Tbd.
A45: [IMAGE] Eff. BF/BOF | B45: Modernized Blast Furnace + Basic Oxygen Furnace | C45: Part of 24.1 (Manufacture of basic iron and steel and of ferro-alloys) | D45: 45092 | E45: zotin | F45: Input data used in the IMAGE model, see also van Ruijven et al. (2016) and van Sluisveld et al. (2021). | G45: 2,3,4,5
...

Sheet ref
B2: Dataset | D2: literature_id | G2: data source name/type/report | H2: authors | I2: title | J2: year | K2: journal_outlet_institution | L2: city | M2: DOI (for papers) and checksum (MD5) for datasets and scripts | N2: URL or link to document, name of document | O2: copyright | P2: archive location | Q2: notes
B3: 4_UPI_CIRCOMOD_D4.1_v1.0 | D3: 1 | G3: U.S. Life Cycle Inventory Database. (2012). National Renewable Energy Laboratory, 2012. Accessed 2018-09-05: https://www.lcacommons.gov/nrel/search | H3: Franklin Associates | I3: Data Details for limestone mining and lime production, Franklin Associates, 2004 | J3: 2004 | N3: https://www.lcacommons.gov/lca-collaboration/National_Renewable_Energy_Laboratory/USLCI/dataset/PROCESS/49e563d8-0cea-3f97-96b8-15787be48b91 | Q3: sample data
B4: 4_UPI_CIRCOMOD_D4.1_v1.0 | D4: 2 | G4: van Ruijven, B. J., van Vuuren, D. P., Boskaljon, W., Neelis, M. L., Saygin, D., & Patel, M. K. (2016). Long-term model-based projections of energy use and CO2 emissions from the global steel and cement industries. Resources, Conservation and Recycling, 112, 15–36. https://doi.org/10.1016/j.resconrec.2016.04.016 | H4: van Ruijven, B. J., van Vuuren, D. P., Boskaljon, W., Neelis, M. L., Saygin, D., & Patel, M. K. | I4: Long-term model-based projections of energy use and CO2 emissions from the global steel and cement industries | J4: 2016 | K4: Resources, Conservation and Recycling | M4: https://doi.org/10.1016/j.resconrec.2016.04.016
B5: 4_UPI_CIRCOMOD_D4.1_v1.0 | D5: 3 | H5: Roorda C, Neelis ML | I5: Inclusion of production, energy use and value added for steel, cement and paper in the TIMER energy demand module | J5: 2006 | K5: Netherlands Environment Assessment Agency | L5: Utrecht | N5: https://dspace.library.uu.nl/bitstream/handle/1874/21828/NWS-E-2006-179.pdf?sequence=1 | P5: No. NWS-E-2006-179
B6: 4_UPI_CIRCOMOD_D4.1_v1.0 | D6: 4 | G6: van Sluisveld, M. A. E., de Boer, H. S., Daioglou, V., Hof, A. F., & van Vuuren, D. P. (2021). A race to zero - Assessing the position of heavy industry in a global net-zero CO2 emissions context. Energy and Climate Change, 2(July), 100051. https://doi.org/10.1016/j.egycc.2021.100051 | H6: van Sluisveld, M. A. E., de Boer, H. S., Daioglou, V., Hof, A. F., & van Vuuren, D. P. | I6: A race to zero - Assessing the position of heavy industry in a global net-zero CO2 emissions context. https://doi.org/10.1016/j.egycc.2021.100051 | J6: 2021 | K6: Energy and Climate Change | M6: https://doi.org/10.1016/j.egycc.2021.100051
B7: 4_UPI_CIRCOMOD_D4.1_v1.0 | D7: 5 | G7: ETP Clean Energy Technology Guide | H7: IEA | J7: 2022 | K7: - | L7: - | M7: - | N7: https://www.iea.org/data-and-statistics/data-tools/etp-clean-energy-technology-guide
B8: 4_UPI_CIRCOMOD_D4.1_v1.0 | D8: 6 | H8: D. Lerede a, C. Bustreo b, F. Gracceva c, M. Saccone a, L. Savoldi | I8: Techno-economic and environmental characterization of industrial technologies for transparent bottom-up energy modeling | J8: 2021 | K8: Renewable and Sustainable Energy Reviews | M8: 10.1016/j.rser.2021.110742 | N8: https://www.sciencedirect.com/science/article/pii/S1364032121000381
B9: 4_UPI_CIRCOMOD_D4.1_v1.0 | D9: 7 | G9: Online | H9: AISI | I9: Steel Production | J9: 2020 | M9: - | N9: https://www.steel.org/steel-technology/steel-production
B10: 4_UPI_CIRCOMOD_D4.1_v1.0 | D10: 8 | G10: Book | H10: P. Cavaliere | I10: Clean Ironmaking and Steelmaking Processes - Efficient Technologies for Greenhouse Emissions Abatement | J10: 2019 | K10: Springer International Publishing | M10: -
B11: 4_UPI_CIRCOMOD_D4.1_v1.0 | D11: 9 | G11: Report | H11: American Iron and Steel Institute | I11: Technology Roadmap Research Program | J11: 2010 | N11: -
B12: 4_UPI_CIRCOMOD_D4.1_v1.0 | D12: 10 | G12: Report | H12: European Commission | I12: Best Available Techniques Reference Document on the Production of Iron and Steel | J12: 2013 | K12: Publications Office of the European Union | L12: Luxembourg | M12: -
B13: 4_UPI_CIRCOMOD_D4.1_v1.0 | D13: 11 | G13: Journal Article | H13: R. Steffen | I13: Direct reduction and smelting reduction – an overview | J13: 1989 | K13: Steel Research | M13: -
B14: 4_UPI_CIRCOMOD_D4.1_v1.0 | D14: 12 | G14: Online | H14: Siemens | I14: Automation technology | J14: 2020 | M14: - | N14: https://new.siemens.com/global/en/company/about/history/technology/drive-and-automation-technology/automation-technology.html
B15: 4_UPI_CIRCOMOD_D4.1_v1.0 | D15: 13 | G15: Online | H15: B. B. Agrawal and A. S. Mathur | I15: New Ironmaking Processes: Relevance to India | J15: 2020 | M15: - | N15: http://www.iim-delhi.com/upload_events/01NewIronmakingProcessRelevanceIndia_RDCIS.pdf
B16: 4_UPI_CIRCOMOD_D4.1_v1.0 | D16: 14 | G16: Report | H16: IEA | I16: Energy Technology Perspectives 2017 | J16: 2017 | K16: IEA Publications | L16: Paris | M16: -
B17: 4_UPI_CIRCOMOD_D4.1_v1.0 | D17: 15 | G17: Online | H17: Tata Steel | I17: HIsarna factsheet | J17: 2020 | M17: - | N17: https://www.tatasteeleurope.com/static_files/Downloads/Corporate/About%20us/hisarna%20factsheet.pdf
B18: 4_UPI_CIRCOMOD_D4.1_v1.0 | D18: 16 | G18: Report | H18: IEA, UNIDO | I18: Technology Roadmap - Carbon Capture and Storage in Industrial Applications | J18: 2011 | K18: IEA Publications | L18: Paris | M18: -
B19: 4_UPI_CIRCOMOD_D4.1_v1.0 | D19: 17 | G19: Report | H19: H. Croezen and M. Korteland | I19: A long-term view of CO2 efficient manufacturing in the European region | J19: 2010 | N19: -
B20: 4_UPI_CIRCOMOD_D4.1_v1.0 | D20: 18 | G20: Journal Article | H20: D. Nuber, H. Eichberger, B. Rollinger | I20: Circored fine ore direct reduction | J20: 2006 | K20: Millenium Steel | M20: -
B21: 4_UPI_CIRCOMOD_D4.1_v1.0 | D21: 19 | G21: Report | H21: J. P. Birat | I21: ULCOS program: status and progress | J21: 2010 | L21: Brussels | M21: -
B22: 4_UPI_CIRCOMOD_D4.1_v1.0 | D22: 20 | G22: Report | H22: R. Remus, M. A. Aguado-Monsonet, S. Roudier, L. Delgado Sancho | I22: Best Available Techniques (BAT) Reference Document for Iron and Steel Production | J22: 2013 | K22: Publications Office of the European Union | L22: Luxembourg | M22: -
B23: 4_UPI_CIRCOMOD_D4.1_v1.0 | D23: 21 | G23: Report | H23: S. A. Singerling, C. A. Tuck, G. M. Bedinger, L. A. Corathers, P. H. Kuck, J. F. Papp, D. A. Polyak, E. K. Schnebele, K. B. Shedd | I23: Geological Survey Minerals Yearbook - Ferroalloys | J23: 2015 | K23: USGS | L23: Reston, USA | M23: -
B24: 4_UPI_CIRCOMOD_D4.1_v1.0 | D24: 22 | G24: Journal Article | H24: P. Mandin, R. Wüthrich, H. Roustan | I24: Industrial Aluminium Production: the Hall-Heroult Process Modelling | J24: 2009 | K24: ECS Transactions | M24: -
B25: 4_UPI_CIRCOMOD_D4.1_v1.0 | D25: 23 | G25: Report | H25: J. A. Moya, A. Boulamati, S. Slingerlan, R. van der Veen, M. Gancheva, K. M. Rademaekers, J. J. P. Kuenen, A. J. H. Visschedijk | I25: Energy Efficiency and GHG Emissions: Prospective Scenarios for the Aluminum Industry | J25: 2015 | K25: Publications Office of the European Union | L25: Luxembourg | M25: -
B26: 4_UPI_CIRCOMOD_D4.1_v1.0 | D26: 24 | G26: Journal Article | H26: A. Boulamanti and J. A. Moya | I26: Production costs of the non-ferrous metals in the EU and other countries: Copper and zinc | J26: 2016 | K26: Resources Policy | M26: -
B27: 4_UPI_CIRCOMOD_D4.1_v1.0 | D27: 25 | G27: Report | H27: G. Cusano, M. R. Gonzalo, F. Farrell, R. Remus, S. Roudier, L. Delgado Sancho | I27: Best Available Techniques (BAT) Reference Document for the Non-Ferrous Metals Industries | J27: 2017 | K27: Publication Office of the European Union | L27: Luxembourg | M27: -
B28: 4_UPI_CIRCOMOD_D4.1_v1.0 | D28: 26 | G28: Report | H28: IEA | I28: Tracking Industrial Energy Efficiency and CO2 Emissions | J28: 2007 | K28: IEA Publications | L28: Paris, France | M28: -
B29: 4_UPI_CIRCOMOD_D4.1_v1.0 | D29: 27 | G29: Book | H29: A. Valero Capilla | I29: Thanatia: the destiny of Earth's mineral resources | J29: 2014 | K29: World Scientific Publishing Co. Pde. Ltd. | L29: Singapore | M29: -
B30: 4_UPI_CIRCOMOD_D4.1_v1.0 | D30: 28 | G30: Online | H30: International tin | I30: Sustainable production | J30: 2020 | M30: - | N30: https://www.internationaltin.org/sustainable-production/
B31: 4_UPI_CIRCOMOD_D4.1_v1.0 | D31: 29 | G31: Journal Article | H31: G. Z. Chen, D. J. Fray, T. W. Farthing | I31: Direct Electrochemical Reduction of Titanium Dioxide to Titanium in Molten Calcium Chloride | J31: 2000 | K31: Nature | M31: DOI:10.1038/35030069
B32: 4_UPI_CIRCOMOD_D4.1_v1.0 | D32: 30 | G32: Online | H32: ITER | I32: Magnets | J32: 2020 | M32: - | N32: https://www.iter.org/mach/Magnets
B33: 4_UPI_CIRCOMOD_D4.1_v1.0 | D33: 31 | G33: Journal Article | H33: N. A. Madlool, R. Saidur, M. S. Hossain, N. Rahim | I33: A critical review on energy use and savings in the cement industries | J33: 2011 | K33: Renewable and Sustainable Energy Reviews | M33: -
B34: 4_UPI_CIRCOMOD_D4.1_v1.0 | D34: 32 | G34: Report | H34: ETSAP | I34: Technology Brief - Cement Production | J34: 2010 | N34: -
B35: 4_UPI_CIRCOMOD_D4.1_v1.0 | D35: 33 | G35: Report | H35: IEAGHG | I35: Deployment of CCS in the cement industry | J35: 2013 | N35: -
B36: 4_UPI_CIRCOMOD_D4.1_v1.0 | D36: 34 | G36: Online | H36: Cembureau | I36: Clinker Substitution | J36: 2020 | M36: - | N36: https://lowcarboneconomy.cembureau.eu/5-parallel-routes/resource-efficiency/clinker-substitution/
B37: 4_UPI_CIRCOMOD_D4.1_v1.0 | D37: 35 | G37: Report | H37: U.S. Environmental Protection Agency | I37: Lime Manufacturing | J37: - | N37: -
B38: 4_UPI_CIRCOMOD_D4.1_v1.0 | D38: 36 | G38: Journal Article | H38: T. Ren, M. Patel, K. Blok | I38: Olefins from conventional and heavy feedstocks: Energy use in steam cracking and alternative processes | J38: 2006 | K38: Energy | M38: -
B39: 4_UPI_CIRCOMOD_D4.1_v1.0 | D39: 37 | G39: Report | H39: IEA | I39: The Future of Petrochemicals - Towards more sustainable plastics and fertilizers | J39: 2018 | K39: IEA Publications | L39: Paris | M39: -
B40: 4_UPI_CIRCOMOD_D4.1_v1.0 | D40: 38 | G40: Book | H40: Z. Salameh | I40: Renewable Energy System Design | J40: 2014 | K40: Elsevier | M40: -
B41: 4_UPI_CIRCOMOD_D4.1_v1.0 | D41: 39 | G41: Report | H41: European Commission | I41: Reference Document on Best Available Techniques for the Manufacture of Large Volume Inorganic Chemicals - Ammonia, Acids and Fertilisers | J41: 2007 | N41: -
...
