Workbook

Sheet Cover
B2: Dataset information | F2: Dataset format information
C3: Column name | D3: Dataset entries
A4: 1 | B4: Identification | C4: dataset_id | D4: auto | F4: IEDC data file
A5: 2 | C5: dataset_name | D5: 3_MC_Electricity_CIRCOMOD_D4.2_2025
A6: 3 | C6: dataset_version | D6: v0 | F6: Format_Version | G6: IEDC_V1
A7: 4 | B7: Grouping | C7: datagroup_id | D7: CIRCOMOD_D4.2 | F7: Dataset_Unit | G7: LIST
A8: 5 | C8: data_category | D8: 3 | F8: Dataset_Uncertainty | G8: LIST
A9: 6 | C9: data_type | D9: Material composition | F9: Dataset_Comment | G9: LIST
A10: 7 | C10: data_layer | D10: Misc. physical units | F10: Dataset_RecordType | G10: LIST | H10: No_Rows | I10: 162
A11: 8 | B11: System location: What elements and objects in the system are described? | C11: process_scope | D11: use phase | F11: Aspects_classifications | G11: Aspects_Attribute_No | H11: DATA | I11: DATA_Info
A12: 9 | C12: process_resolution | D12: 1 end use sector | F12: end-use sector | G12: 1 | H12: value
A13: 10 | C13: product_scope | D13: electricity generation technologies | F13: material | G13: 1 | H13: unit nominator
A14: 11 | C14: product_resolution | D14: around 20 technologies | F14: age-cohort | G14: 1 | H14: unit denominator
A15: 12 | C15: material_scope | D15: engineering materials | F15: region | G15: 1 | H15: stats_array string
A16: 13 | C16: material_resolution | D16: project-wide material | F16: engineering_material | G16: 1 | H16: comment
A17: 14 | C17: regional_scope | D17: global | F17: strategy | G17: 1
A18: 15 | C18: regional_resolution | D18: country average | F18: layer | G18: 1
A19: 16 | C19: temporal_scope | D19: 2010-2050
A20: 17 | C20: temporal_resolution | D20: product specific
A21: 18 | B21: Description | C21: description | D21: Material content of electricity generation technologies
A22: 19 | C22: keywords | D22: material; material content;
A23: 20 | C23: data_provenance | D23: Official data from government institution; Result of academic MFA work
A24: 21 | C24: dataset_size | D24: [filled in later]
A25: 22 | C25: comment | D25: Misc.
A26: 23 | B26: System location: Dataset aspects and semantics. For aspects: [Aspect;symbol;classification]. Mandatory aspects in gray shading. | C26: aspect_1 | D26: end-use sector
A27: 24 | C27: aspect_1_classification | D27: 6
A28: 25 | C28: aspect_2 | D28: material
A29: 26 | C29: aspect_2_classification | D29: 83
A30: 27 | C30: aspect_3 | D30: age-cohort
A31: 28 | C31: aspect_3_classification | D31: 14
A32: 29 | C32: aspect_4 | D32: region
A33: 30 | C33: aspect_4_classification | D33: 2
A34: 31 | C34: aspect_5 | D34: engineering_material
A35: 32 | C35: aspect_5_classification | D35: 4
A36: 33 | C36: aspect_6 | D36: strategy
A37: 34 | C37: aspect_6_classification | D37: 86
A38: 35 | C38: aspect_7 | D38: layer
A39: 36 | C39: aspect_7_classification | D39: 20
A40: 37 | C40: aspect_8 | D40: none
A41: 38 | C41: aspect_8_classification | D41: none
...

Sheet Data
A1: end-use sector | B1: material | C1: age-cohort | D1: region | E1: engineering_material | F1: strategy | G1: layer | H1: value | I1: unit nominator | J1: unit denominator | K1: stats_array string | L1: comment | M1: uncertainy info | N1: Data source | O1: link to log entry
A2: use phase - electricity infrastructure | B2: Generation - Hydro (run-of-river) | C2: various | D2: Global | E2: steel | F2: none | G2: Mass per power capacity | H2: 45 | I2: g | J2: W | K2: none | L2: input data based on multiple sources | M2: 13; 0.44*value; 1.56*value | N2: see log entry | O2: [kalt2021]_material_intensity
A3: use phase - electricity infrastructure | B3: Generation - Hydro (run-of-river) | C3: various | D3: Global | E3: concrete | F3: none | G3: Mass per power capacity | H3: 5250 | I3: g | J3: W | K3: none | L3: input data based on multiple sources | M3: 13; 0.48*value; 1.52*value | N3: see log entry | O3: [kalt2021]_material_intensity
A4: use phase - electricity infrastructure | B4: Generation - Hydro (run-of-river) | C4: various | D4: Global | E4: copper | F4: none | G4: Mass per power capacity | H4: 3.7 | I4: g | J4: W | K4: none | L4: input data based on multiple sources | M4: 13; 0.14*value; 1.86*value | N4: see log entry | O4: [kalt2021]_material_intensity
A5: use phase - electricity infrastructure | B5: Generation - Hydro (run-of-river) | C5: various | D5: Global | E5: aluminium | F5: none | G5: Mass per power capacity | H5: 0.6 | I5: g | J5: W | K5: none | L5: input data based on multiple sources | M5: 13; 0.5*value; 1.5*value | N5: see log entry | O5: [kalt2021]_material_intensity
A6: use phase - electricity infrastructure | B6: Generation - Hydro (storage) | C6: various | D6: Global | E6: steel | F6: none | G6: Mass per power capacity | H6: 25 | I6: g | J6: W | K6: none | L6: input data based on multiple sources | M6: 13; 0.44*value; 1.56*value | N6: see log entry | O6: [kalt2021]_material_intensity
A7: use phase - electricity infrastructure | B7: Generation - Hydro (storage) | C7: various | D7: Global | E7: concrete | F7: none | G7: Mass per power capacity | H7: 2750 | I7: g | J7: W | K7: none | L7: input data based on multiple sources | M7: 13; 0.48*value; 1.52*value | N7: see log entry | O7: [kalt2021]_material_intensity
A8: use phase - electricity infrastructure | B8: Generation - Hydro (storage) | C8: various | D8: Global | E8: copper | F8: none | G8: Mass per power capacity | H8: 3.2 | I8: g | J8: W | K8: none | L8: input data based on multiple sources | M8: 13; 0.14*value; 1.86*value | N8: see log entry | O8: [kalt2021]_material_intensity
A9: use phase - electricity infrastructure | B9: Generation - Hydro (storage) | C9: various | D9: Global | E9: aluminium | F9: none | G9: Mass per power capacity | H9: 0.3 | I9: g | J9: W | K9: none | L9: input data based on multiple sources | M9: 13; 0.5*value; 1.5*value | N9: see log entry | O9: [kalt2021]_material_intensity
A10: use phase - electricity infrastructure | B10: Generation - Geothermal | C10: various | D10: Global | E10: steel | F10: none | G10: Mass per power capacity | H10: 108 | I10: g | J10: W | K10: none | L10: input data based on multiple sources | M10: 13; 1.86*value; 0.14*value | N10: see log entry | O10: [kalt2021]_material_intensity
A11: use phase - electricity infrastructure | B11: Generation - Geothermal | C11: various | D11: Global | E11: concrete | F11: none | G11: Mass per power capacity | H11: 120 | I11: g | J11: W | K11: none | L11: input data based on multiple sources | N11: see log entry | O11: [kalt2021]_material_intensity
A12: use phase - electricity infrastructure | B12: Generation - Geothermal | C12: various | D12: Global | E12: copper | F12: none | G12: Mass per power capacity | H12: 1.7 | I12: g | J12: W | K12: none | L12: input data based on multiple sources | M12: 13; 0.59*value; 1.41*value | N12: see log entry | O12: [kalt2021]_material_intensity
A13: use phase - electricity infrastructure | B13: Generation - Geothermal | C13: various | D13: Global | E13: aluminium | F13: none | G13: Mass per power capacity | H13: 5.3 | I13: g | J13: W | K13: none | L13: input data based on multiple sources | M13: 13; 0.72*value; 1.28*value | N13: see log entry | O13: [kalt2021]_material_intensity
A14: use phase - electricity infrastructure | B14: Generation - Wind Onshore | C14: various | D14: Global | E14: steel | F14: none | G14: Mass per power capacity | H14: 142 | I14: g | J14: W | K14: none | L14: input data based on multiple sources | M14: 13; 1.3*value; 0.7*value | N14: see log entry | O14: [kalt2021]_material_intensity
A15: use phase - electricity infrastructure | B15: Generation - Wind Onshore | C15: various | D15: Global | E15: concrete | F15: none | G15: Mass per power capacity | H15: 502 | I15: g | J15: W | K15: none | L15: input data based on multiple sources | M15: 13; 0.51*value; 1.49*value | N15: see log entry | O15: [kalt2021]_material_intensity
A16: use phase - electricity infrastructure | B16: Generation - Wind Onshore | C16: various | D16: Global | E16: copper | F16: none | G16: Mass per power capacity | H16: 3.6 | I16: g | J16: W | K16: none | L16: input data based on multiple sources | M16: 13; 0.36*value; 1.64*value | N16: see log entry | O16: [kalt2021]_material_intensity
A17: use phase - electricity infrastructure | B17: Generation - Wind Onshore | C17: various | D17: Global | E17: aluminium | F17: none | G17: Mass per power capacity | H17: 2.7 | I17: g | J17: W | K17: none | L17: input data based on multiple sources | M17: 13; 0.3*value; 1.7*value | N17: see log entry | O17: [kalt2021]_material_intensity
A18: use phase - electricity infrastructure | B18: Generation - Wind Offshore | C18: various | D18: Global | E18: steel | F18: none | G18: Mass per power capacity | H18: 400 | I18: g | J18: W | K18: none | L18: input data based on multiple sources | M18: 13; 0.63*value; 1.38*value | N18: see log entry | O18: [kalt2021]_material_intensity
A19: use phase - electricity infrastructure | B19: Generation - Wind Offshore | C19: various | D19: Global | E19: concrete | F19: none | G19: Mass per power capacity | H19: 791 | I19: g | J19: W | K19: none | L19: input data based on multiple sources | M19: 13; 0*value; 2*value | N19: see log entry | O19: [kalt2021]_material_intensity
A20: use phase - electricity infrastructure | B20: Generation - Wind Offshore | C20: various | D20: Global | E20: copper | F20: none | G20: Mass per power capacity | H20: 6.8 | I20: g | J20: W | K20: none | L20: input data based on multiple sources | M20: 13; 0.21*value; 1.79*value | N20: see log entry | O20: [kalt2021]_material_intensity
A21: use phase - electricity infrastructure | B21: Generation - Wind Offshore | C21: various | D21: Global | E21: aluminium | F21: none | G21: Mass per power capacity | H21: 2.7 | I21: g | J21: W | K21: none | L21: input data based on multiple sources | M21: 13; 0.3*value; 1.7*value | N21: see log entry | O21: [kalt2021]_material_intensity
A22: use phase - electricity infrastructure | B22: Generation - PV (rooftop) | C22: various | D22: Global | E22: steel | F22: none | G22: Mass per power capacity | H22: 29 | I22: g | J22: W | K22: none | L22: input data based on multiple sources | M22: 13; 0.28*value; 1.72*value | N22: see log entry | O22: [kalt2021]_material_intensity
A23: use phase - electricity infrastructure | B23: Generation - PV (rooftop) | C23: various | D23: Global | E23: concrete | F23: none | G23: Mass per power capacity | H23: 0 | I23: g | J23: W | K23: none | L23: input data based on multiple sources | N23: see log entry | O23: [kalt2021]_material_intensity
A24: use phase - electricity infrastructure | B24: Generation - PV (rooftop) | C24: various | D24: Global | E24: copper | F24: none | G24: Mass per power capacity | H24: 3.2 | I24: g | J24: W | K24: none | L24: input data based on multiple sources | M24: 13; 0.31*value; 1.69*value | N24: see log entry | O24: [kalt2021]_material_intensity
A25: use phase - electricity infrastructure | B25: Generation - PV (rooftop) | C25: various | D25: Global | E25: aluminium | F25: none | G25: Mass per power capacity | H25: 31.5 | I25: g | J25: W | K25: none | L25: input data based on multiple sources | M25: 13; 0.41*value; 1.59*value | N25: see log entry | O25: [kalt2021]_material_intensity
A26: use phase - electricity infrastructure | B26: Generation - PV (ground-mntd.) | C26: various | D26: Global | E26: steel | F26: none | G26: Mass per power capacity | H26: 111 | I26: g | J26: W | K26: none | L26: input data based on multiple sources | M26: 13; 1.59*value; 0.41*value | N26: see log entry | O26: [kalt2021]_material_intensity
A27: use phase - electricity infrastructure | B27: Generation - PV (ground-mntd.) | C27: various | D27: Global | E27: concrete | F27: none | G27: Mass per power capacity | H27: 383 | I27: g | J27: W | K27: none | L27: input data based on multiple sources | M27: 13; 0.21*value; 1.79*value | N27: see log entry | O27: [kalt2021]_material_intensity
A28: use phase - electricity infrastructure | B28: Generation - PV (ground-mntd.) | C28: various | D28: Global | E28: copper | F28: none | G28: Mass per power capacity | H28: 3.2 | I28: g | J28: W | K28: none | L28: input data based on multiple sources | M28: 13; 0.31*value; 1.69*value | N28: see log entry | O28: [kalt2021]_material_intensity
A29: use phase - electricity infrastructure | B29: Generation - PV (ground-mntd.) | C29: various | D29: Global | E29: aluminium | F29: none | G29: Mass per power capacity | H29: 31.5 | I29: g | J29: W | K29: none | L29: input data based on multiple sources | M29: 13; 0.41*value; 1.59*value | N29: see log entry | O29: [kalt2021]_material_intensity
A30: use phase - electricity infrastructure | B30: Generation - CSP | C30: various | D30: Global | E30: steel | F30: none | G30: Mass per power capacity | H30: 510 | I30: g | J30: W | K30: none | L30: input data based on multiple sources | M30: 13; 0.33*value; 1.67*value | N30: see log entry | O30: [kalt2021]_material_intensity
A31: use phase - electricity infrastructure | B31: Generation - CSP | C31: various | D31: Global | E31: concrete | F31: none | G31: Mass per power capacity | H31: 465 | I31: g | J31: W | K31: none | L31: input data based on multiple sources | M31: 13; 0.22*value; 1.78*value | N31: see log entry | O31: [kalt2021]_material_intensity
A32: use phase - electricity infrastructure | B32: Generation - CSP | C32: various | D32: Global | E32: copper | F32: none | G32: Mass per power capacity | H32: 3.9 | I32: g | J32: W | K32: none | L32: input data based on multiple sources | M32: 13; 0.21*value; 1.79*value | N32: see log entry | O32: [kalt2021]_material_intensity
A33: use phase - electricity infrastructure | B33: Generation - CSP | C33: various | D33: Global | E33: aluminium | F33: none | G33: Mass per power capacity | H33: 13.3 | I33: g | J33: W | K33: none | L33: input data based on multiple sources | M33: 13; 0.2*value; 1.8*value | N33: see log entry | O33: [kalt2021]_material_intensity
A34: use phase - electricity infrastructure | B34: Generation - Bioenergy | C34: various | D34: Global | E34: steel | F34: none | G34: Mass per power capacity | H34: 198 | I34: g | J34: W | K34: none | L34: input data based on multiple sources | M34: 13; 0.35*value; 1.65*value | N34: see log entry | O34: [kalt2021]_material_intensity
A35: use phase - electricity infrastructure | B35: Generation - Bioenergy | C35: various | D35: Global | E35: concrete | F35: none | G35: Mass per power capacity | H35: 540 | I35: g | J35: W | K35: none | L35: input data based on multiple sources | M35: 13; 0.7*value; 1.3*value | N35: see log entry | O35: [kalt2021]_material_intensity
A36: use phase - electricity infrastructure | B36: Generation - Bioenergy | C36: various | D36: Global | E36: copper | F36: none | G36: Mass per power capacity | H36: 2.5 | I36: g | J36: W | K36: none | L36: input data based on multiple sources | N36: see log entry | O36: [kalt2021]_material_intensity
A37: use phase - electricity infrastructure | B37: Generation - Bioenergy | C37: various | D37: Global | E37: aluminium | F37: none | G37: Mass per power capacity | H37: 2.3 | I37: g | J37: W | K37: none | L37: input data based on multiple sources | M37: 13; 0.43*value; 1.57*value | N37: see log entry | O37: [kalt2021]_material_intensity
A38: use phase - electricity infrastructure | B38: Generation - Coal | C38: various | D38: Global | E38: steel | F38: none | G38: Mass per power capacity | H38: 65 | I38: g | J38: W | K38: none | L38: input data based on multiple sources | M38: 13; 0.46*value; 1.54*value | N38: see log entry | O38: [kalt2021]_material_intensity
A39: use phase - electricity infrastructure | B39: Generation - Coal | C39: various | D39: Global | E39: concrete | F39: none | G39: Mass per power capacity | H39: 275 | I39: g | J39: W | K39: none | L39: input data based on multiple sources | M39: 13; 0.36*value; 1.64*value | N39: see log entry | O39: [kalt2021]_material_intensity
A40: use phase - electricity infrastructure | B40: Generation - Coal | C40: various | D40: Global | E40: copper | F40: none | G40: Mass per power capacity | H40: 2 | I40: g | J40: W | K40: none | L40: input data based on multiple sources | M40: 13; -0.5*value; 2.5*value | N40: see log entry | O40: [kalt2021]_material_intensity
...

Sheet log
A1: Log entry name (link to column L on Data sheet) | B1: Which product_type? (CM_4: flow_categories, link to column B on Data sheet) | C1: Which material consuming sector? (CM_6: material_demand_sectors, link to column A on Data sheet) | D1: Date (mm-dd-yyyy) | E1: Who | F1: What - detailed description | G1: List items of ref sheet used
A2: example_1 | B2: concrete_residential_building_multi-familyHouse | C2: Buildings | D2: 45273 | E2: Meng Jiang | F2: Add an example | G2: 2
F3: Additional comments, assumptions, and proxy choices made:
F4: None.
F5: Qualitative evaluation of the data (coverage, overall quality and representativenss, technology readiness, scalability, quality evaluation of the data)
F6: None.
A8: [kalt2021]_material_intensity | B8: electricity generation technologies material intensity | C8: electricity | D8: 07.02.24 | E8: zotin | F8: Multiple sources used in Kalt et al., 2021 | G8: 1 to 23
F9: Additional comments, assumptions, and proxy choices made:
F10: None.
F11: Qualitative evaluation of the data (coverage, overall quality and representativenss, technology readiness, scalability, quality evaluation of the data)
F12: None.
A14: [deetman2021]_material_intensity | B14: Material intensities of electricity generation, storage & distribution | D14: 45629 | E14: deetman | F14: Data used in Deetman et al 2021, based on multiple sources | G14: 24
F15: Additional comments, assumptions, and proxy choices made:
F16: None.
F17: Qualitative evaluation of the data (coverage, overall quality and representativenss, technology readiness, scalability, quality evaluation of the data)
F18: None.
A20: [lines2024]_material_intensity | B20: Material intensities of transmission lines at various voltage levels | D20: 45629 | E20: deetman | F20: Material compositon data per km of transmission/distribution line collected from various studies and processed to represent average values for high voltage (HV: typically >135kV) medium voltage (MV: typically 1-135kV) and low voltage (LV: <1kV) grid lines | G20: 25 to
F21: Additional comments, assumptions, and proxy choices made:
F22: None.
F23: Qualitative evaluation of the data (coverage, overall quality and representativenss, technology readiness, scalability, quality evaluation of the data)
F24: None.
A26: [wang2023]_material_intensity | B26: electricity generation technologies material intensity | C26: electricity | D26: 03/15/2024 | E26: fortes | F26: Multiple sources used in Wang et al., 2023
F27: Additional comments, assumptions, and proxy choices made:
F28: None.
F29: Qualitative evaluation of the data (coverage, overall quality and representativenss, technology readiness, scalability, quality evaluation of the data)
F30: None.
A32: GRO2024_elec_weight | B32: various | C32: electricity | D32: 45386 | E32: Martijn van Engelenburg | F32: Added lightweighting assumptions from GRO2024
F33: Additional comments, assumptions, and proxy choices made:
F34: None.
F35: Qualitative evaluation of the data (coverage, overall quality and representativenss, technology readiness, scalability, quality evaluation of the data)
F36: None.

Sheet ref
B1: Dataset | C1: literature_id | D1: data source name/type/report | E1: authors | F1: title | G1: year | H1: journal_outlet_institution | I1: city | J1: DOI (for papers) and checksum (MD5) for datasets and scripts and URL | K1: URL or link to document, name of document | L1: copyright | M1: archive location | N1: notes
B2: D42_01_MC_MaterialComposition | C2: 1 | D2: journal article | E2: Deriving life cycle assessment coefficients for application in integrated assessment modelling | G2: 2018 | H2: Environ. Modell. Softw | J2: 10.1016/j.envsoft.2017.09.010
B3: D42_01_MC_MaterialComposition | C3: 2 | D3: journal article | E3: M.F. Ashby | F3: Materials for low-carbon power | G3: 2013 | H3: Materials and the Environment | J3: 10.1016/B978-0-12-385971-6.00012-9
B4: D42_01_MC_MaterialComposition | C4: 3 | D4: journal article | E4: A. Beylot, D. Guyonnet, S. Muller, S. Vaxelaire, J. Villeneuve | F4: Mineral raw material requirements and associated climate-change impacts of the French energy transition by 2050 | G4: 2019 | H4: J. Clean. Prod. | J4: 10.1016/j.jclepro.2018.10.154
B5: D42_01_MC_MaterialComposition | C5: 4 | D5: journal article | E5: A. Bonou, A. Laurent, S.I. Olsen | F5: Life cycle assessment of onshore and offshore wind energy-from theory to application | G5: 2016 | H5: Appl. Energy, | J5: 10.1016/j.apenergy.2016.07.058
C6: 5 | D6: journal article | E6: I. Capellán-Pérez, C. de Castro, L.J. Miguel González | F6: Dynamic Energy Return on Energy Investment (EROI) and material requirements in scenarios of global transition to renewable energies | G6: 2019 | H6: Energy Strategy Rev. | J6: 100399, 10.1016/j.esr.2019.100399
C7: 6 | D7: journal article | E7: J. Chipindula, V. Botlaguduru, H. Du, R. Kommalapati, Z. Huque | F7: Life cycle environmental impact of onshore and offshore wind farms in texas | G7: 2018 | H7: Sustainability | J7: 10.3390/su10062022
C8: 7 | D8: report | E8: R. Dones, C. Bauer, R. Bollinger, B. Burger, M. Faist Emmenegger, R. Frischknecht, T. Heck, N. Jungbluth, A. Röder, M. Tuchschmid | F8: Life Cycle Inventories of Energy Systems: Results for Current Systems in Switzerland and Other UCTE Countries | G8: 2007 | H8: Ecoinvent Report No5
C9: 8 | D9: journal article | E9: A. Elshkaki, T.E. Graedel | F9: Dynamic analysis of the global metals flows and stocks in electricity generation technologies | G9: 2013 | H9: J. Clean. Prod. | J9: 10.1016/j.jclepro.2013.07.003
C10: 9 | D10: journal article | E10: Z. Kis, N. Pandya, R.H.E.M Koppelaar | F10: Electricity generation technologies: comparison of materials use, energy return on investment, jobs creation and CO 2 emissions reduction | G10: 2018 | H10: Energy Policy | J10: 10.1016/j.enpol.2018.05.033
C11: 10 | D11: journal article | E11: F. Li, Z. Ye, X. Xiao, J. Xu, G. Liu | F11: Material stocks and flows of power infrastructure development in China | G11: 2020 | H11: Resour. Conservat. Recycl | J11: 10.1016/j.resconrec.2020.104906
C12: 11 | D12: journal article | E12: G. Luderer, M. Pehl, A. Arvesen, T. Gibon, B.L. Bodirsky, H.S. de Boer, O. Fricko, M. Hejazi, F. Humpenöder, G. Iyer, S. Mima, I. Mouratiadou, R.C. Pietzcker, A. Popp, M. van den Berg, D. van Vuuren, E.G. Hertwich | F12: Environmental co-benefits and adverse side-effects of alternative power sector decarbonization strategies | G12: 2019 | H12: Nat. Commun. | J12: 10.1038/s41467-019-13067-8
C13: 12 | D13: journal article | E13: A. Månberger, B. Stenqvist | F13: Global metal flows in the renewable energy transition: exploring the effects of substitutes, technological mix and development | G13: 2018 | H13: Energy Policy | J13: 10.1016/j.enpol.2018.04.056
C14: 13 | D14: journal article | E14: R.L. Moss, E. Tzimas, H. Kara, P. Willis, J. Kooroshy | F14: The potential risks from metals bottlenecks to the deployment of Strategic Energy Technologies | G14: 2013 | H14: Energy Policy | J14: 10.1016/j.enpol.2012.12.053
C15: 14 | D15: journal article | E15: S. Pacca, A. Horvath | F15: Greenhouse gas emissions from building and operating electric power plants in the upper Colorado river basin | G15: 2002 | H15: Environ. Sci. Technol., | J15: 3194-3200, 10.1021/es0155884
C16: 15 | D16: journal article | E16: K. Tokimatsu, M. Höök, B. McLellan, H. Wachtmeister, S. Murakami, R. Yasuoka, M. Nishio | F16: Energy modeling approach to the global energy-mineral nexus: exploring metal requirements and the well-below 2°C target with 100 percent renewable energy | G16: 2018 | H16: Appl. Energy, | J16: 10.1016/j.apenergy.2018.05.047
C17: 16 | D17: journal article | E17: A. Valero, A. Valero, G. Calvo, A. Ortego | F17: Material bottlenecks in the future development of green technologies | G17: 2018 | H17: Renew. Sustain. Energy Rev | J17: 10.1016/j.rser.2018.05.041
C18: 17 | D18: journal article | E18: O. Vidal, B. Goffé, N. Arndt | F18: Metals for a low-carbon society | G18: 2013 | H18: Nat. Geosci. | J18: 10.1038/ngeo1993
C19: 18 | D19: EPD | E19: The International EPD System ( | F19: EPD Database | G19: 2020
C20: 19 | D20: EPD | E20: Siemens Gamesa | F20: Environmental Product Declaration SG 8.0-167 DD | G20: 2019
C21: 20 | D21: life-cycle inventory data | E21: International Institute for Sustainability Analysis and Strategy, | F21: GEMIS 4.9—Global Emissions Model for integrated Systems | G21: 2020 | I21: Darmstadt, Germany | K21: http://iinas.org/gemis-download.html
C22: 21 | D22: report | E22: J.M. Bödeker, M. Bauer, M. Pehnt | F22: Aluminium and Renewable Energy Systems – Prospects For the Sustainable Generation of Electricity and Heat | G22: 2010 | H22: ifeu - Institut für Energie- und Umweltforschung Heidelberg GmbH (2010)
C23: 22 | D23: report | E23: IRENA | F23: Renewable Energy benefits: Leveraging Local Capacity for Solar PV | G23: 2017
C24: 23 | D24: report | E24: E. Rietveld, H. Boonman, T. van Harmelen, M. Hauck, T. Bastein | F24: Global Energy Transitions and Metal Demand. An Introduction and Circular Economy Perspectives | H24: TNO
C25: 24 | D25: journal article | E25: S. Deetman, H.S. de Boer, M. Van Engelenburg, E. van der Voet, D.P. van Vuuren | F25: Projected material requirements for the global electricity infrastructure – generation, transmission and storage | G25: 2021 | H25: Resources, Conservation and Recycling | J25: https://doi.org/10.1016/j.resconrec.2020.105200 | N25: see raw data sheets
C26: 25 | D26: journal article | E26: Jorge, Hawkins, Hertwich | F26: Life cycle assessment of electricity transmission and distribution—part 1: power lines and cables | G26: 2012 | H26: The International Journal of Life Cycle Assessment | J26: https://doi.org/10.1007/s11367-011-0335-1
C27: 26 | D27: journal article | E27: Jones, McManus | F27: Life-cycle assessment of 11 kV electrical overhead lines and underground cables | G27: 2010 | H27: Journal of Cleaner Production | J27: https://doi.org/10.1016/j.jclepro.2010.05.008
C28: 27 | D28: journal article | E28: Turconi, Simonsen, Byriel, Astrup | F28: Life cycle assessment of the Danish electricity distribution network | G28: 2014 | H28: The International Journal of Life Cycle Assessment | J28: https://doi.org/10.1007/s11367-013-0632-y
C29: 28 | D29: journal article | E29: G. Kalt, P. Thunshirn, D. Wiedenhofer, F. Krausmann, W. Haas, H. Haberl | F29: Material stocks in global electricity infrastructures – An empirical analysis of the power sector's stock-flow-service nexus | G29: 2021 | H29: Resources, Conservation and Recycling | J29: https://doi.org/10.1016/j.resconrec.2021.105723
C30: 29 | D30: journal article | E30: J. van Oorschot, B. Sprecher, B. Roelofs, J. van der Horst, E. van der Voet | F30: Towards a low-carbon and circular economy: Scenarios for metal stocks and flows in the Dutch electricity system | G30: 2022 | H30: Resources, Conservation and Recycling | J30: https://doi.org/10.1016/j.resconrec.2021.106105
C31: 30 | D31: journal article | E31: Seaver Wang, Zeke Hausfather, Steven Davis, Juzel Lloyd, Erik B. Olson, Lauren Liebermann, Guido D. Núñez-Mujica, Jameson McBride | F31: Future demand for electricity generation materials under different climate mitigation scenarios | G31: 2023 | H31: Joule | J31: https://doi.org/10.1016/j.joule.2023.01.001 | N31: see raw_data_Wang2023
C32: 31 | D32: Report | E32: UNEP | F32: Global Resources Outlook 2024: Bend the Trend – Pathways to a liveable planet as resource use spikes | G32: 2024 | H32: UNEP | I32: Nairobi | J32: https://wedocs.unep.org/20.500.11822/44902
C33: 32
C34: 33
C35: 34
C36: 35
C37: 36
C38: 37

Sheet raw_data
A1: Raw tables/data could be directly pasted here :)
A3: https://doi.org/10.1016/j.resconrec.2020.105200 | B3: literature_id: 24
A5: Composition of Electricity Generation Technologies (in g/MW) | B5: Steel | C5: Aluminium | D5: Concrete | E5: Plastics | F5: Glass | G5: Cu | H5: Nd | I5: Co | J5: Pb
A6: Solar PV | B6: 150000000 | C6: 10176000 | D6: 0 | E6: 0 | F6: 0 | G6: 6341800 | H6: 0 | I6: 0 | J6: 121643
A7: CSP | B7: 5.7623581e+08 | C7: 5500000 | D7: 1351812440 | E7: 0 | F7: 155986667 | G7: 3145804.8 | H7: 0 | I7: 0 | J7: 0
A8: Wind onshore | B8: 1.2137589e+08 | C8: 868361.91 | D8: 4.3395315e+08 | E8: 0 | F8: 0 | G8: 2730547.9 | H8: 20300 | I8: 0 | J8: 0
A9: Wind offshore | B9: 157942499 | C9: 1438333.3 | D9: 5.0913315e+08 | E9: 0 | F9: 0 | G9: 5571450 | H9: 158337 | I9: 0 | J9: 0
A10: Hydro | B10: 70693939 | C10: 0 | D10: 2832619030 | E10: 0 | F10: 0 | G10: 1699075.3 | H10: 0 | I10: 0 | J10: 5360
A11: Other Renewables | B11: 2.1568296e+08 | C11: 3596539 | D11: 1025503555 | E11: 0 | F11: 0 | G11: 3897735.6 | H11: 35727.4 | I11: 0 | J11: 25401
A12: Nuclear | B12: 43456667 | C12: 78666.667 | D12: 2.3523333e+08 | E12: 0 | F12: 0 | G12: 764800 | H12: 0 | I12: 121 | J12: 33767
A13: Conv. Coal | B13: 84600000 | C13: 504252.24 | D13: 352800000 | E13: 0 | F13: 0 | G13: 1146000 | H13: 0 | I13: 115486 | J13: 0
A14: Conv. Oil | B14: 72900000 | C14: 600000 | D14: 213360000 | E14: 0 | F14: 0 | G14: 762112.9 | H14: 0 | I14: 67282 | J14: 0
A15: Conv. Natural Gas | B15: 4035483.9 | C15: 376451.61 | D15: 43029355 | E15: 0 | F15: 0 | G15: 378225.81 | H15: 0 | I15: 19078 | J15: 0
A16: Waste | B16: 72900000 | C16: 600000 | D16: 213360000 | E16: 0 | F16: 0 | G16: 762112.9 | H16: 0 | I16: 67282 | J16: 0
A17: IGCC | B17: 34900000 | C17: 504252.24 | D17: 165000000 | E17: 0 | F17: 0 | G17: 1146000 | H17: 0 | I17: 115486 | J17: 0
... A32: CHP Biomass + CCS | B32: 43138518 | C32: 262500 | D32: 243796875 | E32: 0 | F32: 0 | G32: 3629400 | H32: 0 | I32: 74782 | J32: 0
A34: Composition of grid lines (in kg/km line length) | B34: Steel | C34: Aluminium | D34: Concrete | E34: Plastics | F34: Glass | G34: Cu | H34: Nd | I34: Co | J34: Pb
A35: HV overhead | B35: 52266 | C35: 12883 | D35: 209137.5 | E35: 0 | F35: 1096.5 | G35: 0 | H35: 0 | I35: 0 | J35: 0
A36: HV underground | B36: 0 | C36: 0 | D36: 17500 | E36: 2300 | F36: 0 | G36: 11650 | H36: 0 | I36: 0 | J36: 14050
A37: MV overhead | B37: 802.33333 | C37: 0 | D37: 0 | E37: 19.333333 | F37: 0 | G37: 1487.6667 | H37: 0 | I37: 0 | J37: 0
A38: MV underground | B38: 0 | C38: 823.58333 | D38: 0 | E38: 1346.9167 | F38: 0 | G38: 662.91667 | H38: 0 | I38: 0 | J38: 0
A39: LV overhead | B39: 0 | C39: 981 | D39: 0 | E39: 378 | F39: 0 | G39: 0 | H39: 0 | I39: 0 | J39: 0
A40: LV underground | B40: 177 | C40: 531 | D40: 0 | E40: 0 | F40: 0 | G40: 0 | H40: 0 | I40: 0 | J40: 0
A42: Composition of transformer substations (in kg/unit) | B42: Steel | C42: Aluminium | D42: Concrete | E42: Plastics | F42: Glass | G42: Cu | H42: Nd | I42: Co | J42: Pb
A43: Hv Substation | B43: 14652.055 | C43: 33204.29 | D43: 123900 | E43: 302.035 | F43: 0.05 | G43: 4611.388 | H43: 0 | I43: 0 | J43: 0.002
A44: Mv Substation | B44: 1814.5833 | C44: 1228.3333 | D44: 127020.83 | E44: 0 | F44: 0 | G44: 279.16667 | H44: 0 | I44: 0 | J44: 0
A45: Lv Substation | B45: 38.420135 | C45: 1228.3333 | D45: 476.32813 | E45: 0 | F45: 0 | G45: 0.54394161 | H45: 0 | I45: 0 | J45: 0
A46: Hv Transformer | B46: 295999 | C46: 496.75 | D46: 648000 | E46: 0 | F46: 0 | G46: 76047 | H46: 0 | I46: 0 | J46: 0
A47: Mv Transformer | B47: 22658.833 | C47: 21 | D47: 46825.556 | E47: 0 | F47: 0 | G47: 6877.27 | H47: 0 | I47: 0 | J47: 0.088333333
A48: Lv Transformer | B48: 479.755 | C48: 84.905 | D48: 175.59583 | E48: 0 | F48: 0 | G48: 13.4 | H48: 0 | I48: 0 | J48: 0
A50: Composition of electricity storage technologies (in fraction of total weight) | B50: Steel | C50: Aluminium | D50: Concrete | E50: Plastics | F50: Glass | G50: Cu | H50: Nd | I50: Co | J50: Pb
A51: Flywheel | B51: 0.60858277 | C51: 0.20239317 | D51: 0 | E51: 0 | F51: 0 | G51: 0.013558201 | H51: 0.006416159 | I51: 0 | J51: 0
A52: Compressed Air | B52: 0.98428224 | C52: 0.007689705 | D52: 0 | E52: 0 | F52: 0 | G52: 0.008028052 | H52: 0 | I52: 0 | J52: 0
A53: Hydrogen FC | B53: 0.96167444 | C53: 0.00471409 | D53: 0 | E53: 0 | F53: 0 | G53: 0.017677839 | H53: 0 | I53: 0 | J53: 0
A54: NiMH | B54: 0.1 | C54: 0.00255 | D54: 0 | E54: 0.21 | F54: 0 | G54: 0.01769956 | H54: 0.047101968 | I54: 0.00255 | J54: 0
A55: Deep-cycle Lead-Acid | B55: 0 | C55: 0 | D55: 0 | E55: 0.1 | F55: 0.02 | G55: 0 | H55: 0 | I55: 0 | J55: 0.61
A56: LMO | B56: 0.2147 | C56: 0.0374 | D56: 0 | E56: 0.0839875 | F56: 0 | G56: 0.1003 | H56: 0 | I56: 0 | J56: 0
A57: NMC | B57: 0.2147 | C57: 0.0374 | D57: 0 | E57: 0.0839875 | F57: 0 | G57: 0.1003 | H57: 0 | I57: 0.076449528 | J57: 0
A58: NCA | B58: 0.007413299 | C58: 0.24371619 | D58: 0 | E58: 0 | F58: 0 | G58: 0.1247216 | H58: 0 | I58: 0.031307668 | J58: 0
A59: LFP | B59: 0.1408805 | C59: 0.05 | D59: 0 | E59: 0.1 | F59: 0 | G59: 0.05 | H59: 0 | I59: 0 | J59: 0
...

Sheet raw_data_Wang2023
A1: Assuming that for onshore wind turbines, material use of non-RE materials is the same for DD vs AG types unless explicitly stated in source. Likewise for offshore turbines. | Q1: Technology | R1: Technology | S1: MateriAluminum | T1: Intensity value (tons/GW) | U1: Source | W1: Onshore_DD_PMG | X1: onshore wind turbine with permanent magnet gearbox direct drive
A2: Assuming that onshore and offshore PM turbines have similar intensitites of rare earth usage | Q2: Onshore_DD_PMG | R2: Generation - Wind Onshore | S2: Aluminum | T2: 13200 | U2: Garrett + Ronde 2011 | W2: Onshore_AG | X2: onshore wind turbine with asynchronous gearbox drive
A3: GREEN = final values (precise shading of green is immaterial) | Q3: Onshore_DD_PMG | R3: Generation - Wind Onshore | S3: Cement | T3: 38717 | U3: Garrett + Ronde 2011 | W3: Offshore_DD_PMG | X3: offshore wind turbine with permanent magnet gearbox direct drive
A4: RED = rejected values | Q4: Onshore_DD_PMG | R4: Generation - Wind Onshore | S4: Cement | T4: 41456 | U4: Wilburn 2011 | W4: Offshore_AG | X4: offshore wind turbine with asynchronous gearbox drive
Q5: Onshore_DD_PMG | R5: Generation - Wind Onshore | S5: Cement | T5: 60070 | U5: Garrett + Ronde 2011 | W5: CSI_PV | X5: crystalline silicon solar photovoltaic
A6: WIND | Q6: Onshore_DD_PMG | R6: Generation - Wind Onshore | S6: Cement | T6: 64320 | U6: Wilburn 2011 | W6: CIGS | X6: copper indium gallium selenide thin-film solar photovoltaic
A7: 2015 Razdan + Garrett (a) | Q7: Onshore_DD_PMG | R7: Generation - Wind Onshore | S7: Copper | T7: 3320 | U7: Garrett + Ronde 2011 | W7: CDTE | X7: cadmium telluride thin-film solar photovoltaic
A8: Life Cycle Assessment of Electricity Production from an onshore V100-2.0 MW Wind Plant | Q8: Onshore_DD_PMG | R8: Generation - Wind Onshore | S8: Copper | T8: 3000 | U8: Wilburn 2011 | W8: ASIGE | X8: amorphous silicon germanium thin-film solar photovoltaic
A9: https://www.vestas.com/~/media/vestas/about/sustainability/pdfs/lcav10020mw181215.pdf | Q9: Onshore_DD_PMG | R9: Generation - Wind Onshore | S9: Copper | T9: 4700 | U9: Habib + Wenzel 2016
A10: Numbers taken from Table 6, summed across turbines, foundations, cables, switchgears, and transformer | Q10: Onshore_DD_PMG | R10: Generation - Wind Onshore | S10: Copper | T10: 5761 | U10: BBF Associates 2011
A11: Metric tons for a 50MW power plant of V100-2.0 MW onshore turbines, no permanent magnets | Q11: Onshore_DD_PMG | R11: Generation - Wind Onshore | S11: Copper | T11: 2994 | U11: BBF Associates 2011
B12: tons | C12: tons/GW | D12: Notes | Q12: Onshore_DD_PMG | R12: Generation - Wind Onshore | S12: Copper | T12: 6759 | U12: BBF Associates 2011
A13: Concrete | B13: 20067 | C13: 401340 | D13: Concrete C12, C30, C45, amounts unspecified. LCA used C12/15 and C30/37, also employing C30/37 parameters for C45 | Q13: Onshore_DD_PMG | R13: Generation - Wind Onshore | S13: Copper | T13: 2540 | U13: BBF Associates 2011
A14: Steel/cast steel/sintered steel, sum of Unalloyed, low alloyed and Highly alloyed, plus cast iron | B14: 6024 | C14: 120480 | Q14: Onshore_DD_PMG | R14: Generation - Wind Onshore | S14: Copper | T14: 3538 | U14: BBF Associates 2011
A15: Copper | B15: 83 | C15: 1660 | Q15: Onshore_DD_PMG | R15: Generation - Wind Onshore | S15: Dy | T15: 12 | U15: DOE 2011
A16: Copper alloys | B16: 2 | C16: 40 | Q16: Onshore_DD_PMG | R16: Generation - Wind Onshore | S16: Dy | T16: 28 | U16: Hoenderdaal et al 2013
A17: Sum of Copper and Copper alloys | B17: 85 | C17: 1700 | Q17: Onshore_DD_PMG | R17: Generation - Wind Onshore | S17: Fiberglass (ceramic/glass) | T17: 9580 | U17: Garrett + Ronde 2011
A18: Aluminum and Aluminum alloys | B18: 245 | C18: 4900 | Q18: Onshore_DD_PMG | R18: Generation - Wind Onshore | S18: Fiberglass (ceramic/glass) | T18: 6800 | U18: Wilburn 2011
A19: Fiberglass (ceramic/glass) | B19: 449 | C19: 8980 | Q19: Onshore_DD_PMG | R19: Generation - Wind Onshore | S19: Nd | T19: 186 | U19: DOE 2011
Q20: Onshore_DD_PMG | R20: Generation - Wind Onshore | S20: Nd | T20: 216 | U20: Wilburn 2011
A21: Conversion of tons concrete to tons cement | B21: Concrete volume (m^3) per GW | Q21: Onshore_DD_PMG | R21: Generation - Wind Onshore | S21: Nd | T21: 198 | U21: Hoenderdaal et al 2013
A22: Assuming 1600 kg/m^3 | B22: 250837.5 | Q22: Onshore_DD_PMG | R22: Generation - Wind Onshore | S22: Ni | T22: 377 | U22: Fizaine + Court 2015
A23: Assuming 2500 kg/m^3 | B23: 160536 | Q23: Onshore_DD_PMG | R23: Generation - Wind Onshore | S23: Steel | T23: 122780 | U23: Garrett + Ronde 2011
Q24: Onshore_DD_PMG | R24: Generation - Wind Onshore | S24: Steel | T24: 123000 | U24: Wilburn 2011
B25: Cement (kg) per GW | C25: Cement (tons) per GW | Q25: Onshore_AG | R25: Generation - Wind Onshore | S25: Aluminum | T25: 4900 | U25: Razdan + Garrett 2015a
A26: 1600 kg/m^3 density and 165 kg/m^3 cement content | B26: 41388188 | C26: 41388.188 | Q26: Onshore_AG | R26: Generation - Wind Onshore | S26: Aluminum | T26: 5080 | U26: Razdan + Garrett 2015b
A27: 2500 kg/m^3 density and 400 kg/m^3 cement content | B27: 64214400 | C27: 64214.4 | Q27: Onshore_AG | R27: Generation - Wind Onshore | S27: Cement | T27: 41388 | U27: Razdan + Garrett 2015a
Q28: Onshore_AG | R28: Generation - Wind Onshore | S28: Cement | T28: 47099 | U28: Razdan + Garrett 2015b
A29: 2015 Razdan + Garrett (b) | Q29: Onshore_AG | R29: Generation - Wind Onshore | S29: Cement | T29: 41456 | U29: Wilburn 2011
A30: Life Cycle Assessment of Electricity Production from an onshore V110-2.0 MW Wind Plant | Q30: Onshore_AG | R30: Generation - Wind Onshore | S30: Cement | T30: 64214 | U30: Razdan + Garrett 2015a
A31: https://www.vestas.com/~/media/vestas/about/sustainability/pdfs/lcav11020mw181215.pdf | Q31: Onshore_AG | R31: Generation - Wind Onshore | S31: Cement | T31: 73075 | U31: Razdan + Garrett 2015b
A32: Numbers taken from Table 6, summed across turbines, foundations, cables, switchgears, and transformer | Q32: Onshore_AG | R32: Generation - Wind Onshore | S32: Cement | T32: 64320 | U32: Wilburn 2011
A33: Metric tons for a 50MW power plant of V110-2.0 MW onshore turbines, no permanent magnets | Q33: Onshore_AG | R33: Generation - Wind Onshore | S33: Copper | T33: 1700 | U33: Razdan + Garrett 2015a
B34: tons | C34: tons/GW | D34: Notes | Q34: Onshore_AG | R34: Generation - Wind Onshore | S34: Copper | T34: 1740 | U34: Razdan + Garrett 2015b
A35: Concrete | B35: 22836 | C35: 456720 | D35: Concrete C12, C30, C45, amounts unspecified. LCA used C12/15 and C30/37, also employing C30/37 parameters for C45 | Q35: Onshore_AG | R35: Generation - Wind Onshore | S35: Copper | T35: 1850 | U35: Garcia-Olivares et al 2012
A36: Steel/cast steel/sintered steel, sum of Unalloyed, low alloyed and Highly alloyed | B36: 6524 | C36: 130480 | Q36: Onshore_AG | R36: Generation - Wind Onshore | S36: Fiberglass (ceramic/glass) | T36: 8980 | U36: Razdan + Garrett 2015a
A37: Copper | B37: 85 | C37: 1700 | Q37: Onshore_AG | R37: Generation - Wind Onshore | S37: Fiberglass (ceramic/glass) | T37: 7400 | U37: Razdan + Garrett 2015b
A38: Copper alloys | B38: 2 | C38: 40 | Q38: Onshore_AG | R38: Generation - Wind Onshore | S38: Fiberglass (ceramic/glass) | T38: 6800 | U38: Wilburn 2011
A39: Sum of Copper and Copper alloys | B39: 87 | C39: 1740 | Q39: Onshore_AG | R39: Generation - Wind Onshore | S39: Ni | T39: 377 | U39: Fizaine + Court 2015
A40: Aluminum and Aluminum alloys | B40: 254 | C40: 5080 | Q40: Onshore_AG | R40: Generation - Wind Onshore | S40: Steel | T40: 120480 | U40: Razdan + Garrett 2015a
...
